I'm sorry, but an uncaught exception occurred.

While running game code:
  File "game/labels.rpy", line 247, in script
    if trigger_dino:
  File "game/labels.rpy", line 247, in <module>
    if trigger_dino:
NameError: name 'trigger_dino' is not defined

-- Full Traceback ------------------------------------------------------------

Full traceback:
  File "game/labels.rpy", line 247, in script
    if trigger_dino:
  File "A:\Загрузки\Шмотки\Собираем шмотки\RenPy\renpy-7.3.5-sdk/renpy/ast.py", line 1892, in execute
    if renpy.python.py_eval(condition):
  File "A:\Загрузки\Шмотки\Собираем шмотки\RenPy\renpy-7.3.5-sdk/renpy/python.py", line 2249, in py_eval
    return py_eval_bytecode(code, globals, locals)
  File "A:\Загрузки\Шмотки\Собираем шмотки\RenPy\renpy-7.3.5-sdk/renpy/python.py", line 2242, in py_eval_bytecode
    return eval(bytecode, globals, locals)
  File "game/labels.rpy", line 247, in <module>
    if trigger_dino:
NameError: name 'trigger_dino' is not defined

Windows-10-10.0.19041
Ren'Py 7.4.6.1693
Я не буду искать оправданий 0.1-beta
Tue Jul 20 01:53:19 2021
